Workbook

Sheet Read me
A1: TUTOR test suite
A2: Generated 2026-09-29 by backend/qa/build_test_suite.py
A3: Summary
A4: Manual cases | B4: =COUNTA('Manual cases'!$A$2:$A$96) -> 95 | C4: Written in docs/testing/test-cases/*.md
A5: Priority P1 | B5: =COUNTIF('Manual cases'!$E$2:$E$96,"P1") -> 64 | C5: Must pass before any release
A6: Priority P2 | B6: =COUNTIF('Manual cases'!$E$2:$E$96,"P2") -> 26
A7: Priority P3 | B7: =COUNTIF('Manual cases'!$E$2:$E$96,"P3") -> 5
A8: With automated coverage | B8: =COUNTIF('Manual cases'!$K$2:$K$96,">0") -> 84 | C8: Automated tests exist too
A9: Automated coverage % | B9: =IF(B4=0,0,B8/B4) -> 0.88421053 | C9: Share of manual cases also covered by automation
A10: Status: Pass | B10: =COUNTIF('Manual cases'!$N$2:$N$96,"Pass") -> 0 | C10: Filled in by testers in 'Manual cases'
A11: Status: Fail | B11: =COUNTIF('Manual cases'!$N$2:$N$96,"Fail") -> 0 | C11: Every Fail needs a Bug ID
A12: Status: Blocked | B12: =COUNTIF('Manual cases'!$N$2:$N$96,"Blocked") -> 0 | C12: Can't be run (environment, missing feature)
A13: Status: Not run | B13: =COUNTIF('Manual cases'!$N$2:$N$96,"Not run") -> 95
A14: Pass rate (of cases run) | B14: =IF((B10+B11+B12)=0,0,B10/(B10+B11+B12)) -> 0 | C14: Pass ÷ (Pass + Fail + Blocked)
A15: Automated tests | B15: =COUNTA('Automated tests'!$A$2:$A$186) -> 185 | C15: Django tests; run by ./dev.sh and CI
A16: Smoke checks | B16: =COUNTA('Smoke checks'!$A$2:$A$43) -> 42 | C16: Black-box checks over HTTP
A17: Requirements without a manual case | B17: =COUNTIF(Traceability!$H$2:$H$45,"No manual case") -> 15 | C17: Planned features show here until they are built
A19: How to use
A20: 1 | C20: Filter 'Manual cases' by Area or Priority, put your name in Assignee (yellow cells are yours to fill).
A21: 2 | C21: Run the case exactly as written. Accounts are in 'Demo accounts' and docs/testing/demo-data.md.
A22: 3 | C22: Set Status, Tested on and Build / commit. For every Fail, add a row in 'Bug log' and put its ID in Bug ID.
A23: 4 | C23: Don't edit case text here: change docs/testing/test-cases/*.md in a pull request, then rebuild.
A24: Statuses | C24: Not run · Pass · Fail · Blocked · N/A
A25: Environments | C25: Local = your machine with tester tools (dev outbox). Hosted = https://tutor-platform-ovlg.onrender.com
A26: Severity | C26: Critical: data leak, security or consent bypass · High: a P1 case fails · Medium: a P2 case fails · Low: cosmetic
A27: Rebuild | C27: From backend/: python qa/build_test_suite.py (also validates the automation map)

Sheet Manual cases
A1: ID | B1: Area | C1: Section | D1: Title | E1: Priority | F1: Requirements | G1: Environment | H1: Preconditions / accounts | I1: Steps | J1: Expected result | K1: Automated tests | L1: Automated by | M1: Assignee | N1: Status | O1: Tested on | P1: Build / commit | Q1: Bug ID | R1: Notes
A2: TC-SET-1 | B2: Accounts & consent | C2: Setup | D2: Health check | E2: P1 | F2: NFR-AVAIL-1 | G2: Local | I2: `GET /health`. | J2: `200 {"ok": true, "db": true}`. | K2: 3 | L2: apps.accounts.tests.HealthTests.test_health apps.accounts.tests.HealthTests.test_health_is_503_when_the_database_is_unreachable hosted:H1 | N2: Not run
A3: TC-SET-2 | B3: Accounts & consent | C3: Setup | D3: Smoke test passes | E3: P1 | G3: Local | I3: run `python qa/smoke_test.py`. | J3: every line `PASS`, last line `N/N checks passed`. | K3: 1 | L3: smoke:S0 | N3: Not run
A4: TC-SET-3 | B4: Accounts & consent | C4: Setup | D4: Logged-in POST works from the docs page | E4: P1 | F4: NFR-SEC-2 | G4: Local | H4: logged in as `student_enrolled` via `POST /auth/login` in the docs page, then page reloaded (Ctrl+F5). | I4: `POST /lessons/{id}/finish` for any AI Foundations lesson. | J4: `200`. A `403` mentioning CSRF is a High bug. | K4: 1 | L4: apps.accounts.test_api.SecureByDefaultTests.test_docs_page_sends_csrf_token | N4: Not run
A5: TC-ACC-01 | B5: Accounts & consent | C5: Sign-up and login | D5: Student sign-up | E5: P1 | F5: FR-ACC-1, FR-ACC-4 | G5: Local | I5: `POST /auth/signup/student` with name, mobile `98xxxxxxxx` (new), password, `class_number: 8`, `board_code: "CBSE"`, city, `parent_contact` (another new mobile). | J5: `201`; `mobile` returned as `+9198…`; `student.status = "awaiting_consent"`; outbox for the parent has an `/approve/<token>` link; outbox for the student has a 6-digit code. | K5: 2 | L5: apps.accounts.test_api.SignupAndApprovalFlow.test_student_signup_waits_for_parent smoke:A1 | N5: Not run
A6: TC-ACC-02 | B6: Accounts & consent | C6: Sign-up and login | D6: Parent sign-up and contact verification | E6: P1 | F6: FR-ACC-2 | G6: Local | I6: `POST /auth/signup/parent`; read the code from the outbox; `POST /auth/otp/verify` with `purpose: "verify_contact"`. | J6: `201` then `200` with `mobile_verified: true`. | K6: 2 | L6: apps.accounts.test_api.SignupAndApprovalFlow.test_full_approval smoke:A5 | N6: Not run
A7: TC-ACC-03 | B7: Accounts & consent | C7: Sign-up and login | D7: Duplicate sign-up refused | E7: P1 | F7: FR-ACC-1 | G7: Local | I7: repeat TC-ACC-01 with the same mobile. | J7: `409`, `code: "already_registered"`. | K7: 1 | L7: apps.accounts.test_api.LoginAndErrors.test_duplicate_signup | N7: Not run
A8: TC-ACC-04 | B8: Accounts & consent | C8: Sign-up and login | D8: Validation errors | E8: P2 | F8: FR-ACC-1 | G8: Local | I8: sign up with (a) no email and no mobile, (b) `class_number: 13`, (c) `board_code: "XYZ"`, (d) password `12345678`, (e) parent contact equal to the student's own. | J8: `400`, `code: "validation_error"`, the offending field named in `fields` (or `non_field` for (a)). | K8: 1 | L8: apps.accounts.test_api.LoginAndErrors.test_validation_error_format | N8: Not run
A9: TC-ACC-05 | B9: Accounts & consent | C9: Sign-up and login | D9: Login with email, 10-digit mobile and +91 mobile | E9: P1 | F9: FR-ACC-1 | G9: Local | I9: `POST /auth/login` as `student_enrolled` using `esha@test.tutor`, `9000000003` and `+919000000003`. | J9: `200` each time; `GET /me` returns Esha. | K9: 3 | L9: apps.accounts.test_api.LoginAndErrors.test_login_with_plain_10_digit_mobile apps.accounts.tests.LoginTests.test_login_with_email apps.accounts.tests.LoginTests.test_login_with_mobile | N9: Not run
A10: TC-ACC-06 | B10: Accounts & consent | C10: Sign-up and login | D10: Wrong password | E10: P1 | G10: Local | I10: `POST /auth/login` as `esha@test.tutor` with a wrong password, then with `nobody@test.tutor`. | J10: `400`, `code: "invalid_credentials"`; message doesn't reveal whether the account exists. | K10: 2 | L10: apps.accounts.test_api.LoginAndErrors.test_wrong_password hosted:X4 | N10: Not run
A11: TC-ACC-07 | B11: Accounts & consent | C11: Sign-up and login | D11: Logout | E11: P2 | G11: Local | I11: `POST /auth/logout`, then `GET /me`. | J11: `200`, then `401 not_authenticated`. | K11: 0 | N11: Not run
A12: TC-ACC-08 | B12: Accounts & consent | C12: Sign-up and login | D12: Password reset | E12: P1 | F12: FR-ACC-2 | G12: Local | I12: `POST /auth/otp/send` (`purpose: "reset_password"`) for `9000000002`; take the code from the outbox; `POST /auth/password/reset` with a new strong password; log in with it. Afterwards run `seed_test_accounts` to restore. | J12: `200`, `200`, login succeeds with the new password and fails with the old one. | K12: 1 | L12: apps.accounts.test_api.LoginAndErrors.test_password_reset | N12: Not run
A13: TC-ACC-09 | B13: Accounts & consent | C13: Sign-up and login | D13: Codes: expiry, attempts, rate limit | E13: P2 | F13: FR-ACC-2 | G13: Local | I13: (a) verify with a wrong code 5 times, then the right one; (b) request 6 codes within 10 minutes for one contact. | J13: (a) all fail with `invalid_code`, and the right code also fails after 5 wrong tries; (b) 6th request `429 limit_reached`. | K13: 1 | L13: apps.accounts.test_security.RateLimitTests.test_one_time_code_endpoints_are_rate_limited | N13: Not run
A14: TC-ACC-10 | B14: Accounts & consent | C14: Sign-up and login | D14: No code for unknown contacts | E14: P1 | F14: FR-ACC-3 | G14: Local | I14: `POST /auth/otp/send` for an unregistered number. | J14: `200` with the generic message; outbox has no message for that number. | K14: 1 | L14: apps.accounts.test_api.LoginAndErrors.test_otp_not_sent_to_unknown_contact | N14: Not run
A15: TC-CON-01 | B15: Accounts & consent | C15: Parent approval | D15: Approval link details | E15: P1 | F15: FR-ACC-4 | G15: Local | H15: TC-ACC-01 done. | I15: `GET /consent/link/<token>`. | J15: `200`: child's first name only, class label, consent text and version. | K15: 1 | L15: smoke:A6 | N15: Not run
A16: TC-CON-02 | B16: Accounts & consent | C16: Parent approval | D16: Approve | E16: P1 | F16: FR-ACC-4, FR-ACC-5 | G16: Local | H16: verified parent logged in (TC-ACC-02). | I16: `POST /consent/link/<token>/approve` `{"relationship": "mother", "accept": true}`. | J16: `200`; student's `GET /me` shows `status: "active"`; parent's `GET /me` lists the child; Admin → Consent records shows a record with text version and IP; Admin → Audit log shows `consent.given`. | K16: 3 | L16: apps.accounts.test_api.SignupAndApprovalFlow.test_full_approval smoke:A7 smoke:A8 | N16: Not run
A17: TC-CON-03 | B17: Accounts & consent | C17: Parent approval | D17: Unverified parent can't approve | E17: P1 | G17: Local | I17: new parent signs up but doesn't verify, then approves. | J17: `403 contact_not_verified`. | K17: 1 | L17: apps.accounts.test_api.SignupAndApprovalFlow.test_parent_must_verify_contact_first | N17: Not run
A18: TC-CON-04 | B18: Accounts & consent | C18: Parent approval | D18: Consent box must be ticked | E18: P2 | G18: Local | I18: approve with `accept: false`. | J18: `400 validation_error`, field `accept`. | K18: 0 | N18: Not run
A19: TC-CON-05 | B19: Accounts & consent | C19: Parent approval | D19: Link is single-use | E19: P1 | G19: Local | I19: approve twice. | J19: second call `410 link_expired`. | K19: 0 | N19: Not run
A20: TC-CON-06 | B20: Accounts & consent | C20: Parent approval | D20: "Not my child" | E20: P1 | G20: Local | I20: `POST /consent/link/<token>/report` (logged out is fine); then `GET` the link. | J20: `200`, then `410`; Admin → Approval requests shows status `reported`. | K20: 1 | L20: apps.accounts.test_api.SignupAndApprovalFlow.test_not_my_child | N20: Not run
A21: TC-CON-07 | B21: Accounts & consent | C21: Parent approval | D21: Resend limit | E21: P2 | G21: Local | H21: logged in as a waiting student. | I21: `POST /consent/requests/resend` three times. | J21: first two `200` (a new link each time; the old link stops working), third `429 limit_reached`. | K21: 1 | L21: apps.accounts.test_api.SignupAndApprovalFlow.test_resend_limit | N21: Not run
A22: TC-CON-08 | B22: Accounts & consent | C22: Parent approval | D22: Change parent contact | E22: P2 | G22: Local | I22: `PATCH /consent/requests/parent-contact` with a new email. | J22: `200`; outbox for that email has a link; the previous link returns `410`. | K22: 1 | L22: apps.accounts.test_api.SignupAndApprovalFlow.test_change_parent_contact | N22: Not run
A23: TC-CON-09 | B23: Accounts & consent | C23: Parent approval | D23: Second guardian refused (v1) | E23: P2 | F23: FR-ACC-6 | G23: Local | H23: a student already approved by parent A. | I23: a second verified parent tries to approve a new link for the same student. | J23: `409 already_has_guardian`. | K23: 1 | L23: apps.accounts.tests.GuardianConsentTests.test_only_one_active_primary_guardian | N23: Not run
A24: TC-CON-10 | B24: Accounts & consent | C24: Parent approval | D24: Parent adds a child directly | E24: P1 | G24: Local | I24: as `parent`, `POST /parent/children` with name, own email for the child, password, class 10, `ICSE`, city. | J24: `201`, status `active`; the child can log in and open a free lesson. | K24: 1 | L24: apps.accounts.test_api.ParentManagesChildren.test_add_child_withdraw_and_restore | N24: Not run
A25: TC-CON-11 | B25: Accounts & consent | C25: Parent approval | D25: Withdraw and restore consent | E25: P1 | F25: FR-ACC-7 | G25: Local | I25: as `parent`, withdraw for Asha; as Asha open a lesson; parent restores; Asha opens the lesson again. | J25: `200`; `403 consent_required`; `200`; `200`. Audit log shows `consent.withdrawn` and `consent.restored`. | K25: 5 | L25: apps.accounts.test_api.ParentManagesChildren.test_add_child_withdraw_and_restore smoke:P1 smoke:P2 smoke:P3 smoke:P4 | N25: Not run
A26: TC-ADM-01 | B26: Admin | D26: Users list and search | E26: P2 | G26: Local | I26: in `/admin/` → Users, search for `Kabir`, `rahul@test.tutor` and `9000000022`; filter by account type *Parent*. | J26: search by name, email or mobile finds the test accounts; filter by account type works. | K26: 0 | N26: Not run
A27: TC-ADM-02 | B27: Admin | D27: Create a user in admin | E27: P2 | G27: Local | I27: add a user with only a mobile. | J27: saved. Adding a user with neither email nor mobile is refused. | K27: 0 | N27: Not run
A28: TC-ADM-03 | B28: Admin | D28: Grant an entitlement | E28: P1 | G28: Local | I28: follow the tester guide §4. | J28: the student can open paid lessons immediately. | K28: 0 | N28: Not run
A29: TC-ADM-04 | B29: Admin | D29: Publish content | E29: P1 | F29: FR-CON-3 | G29: Local | I29: create a new content version for *What is data?* with status `approved`, a reviewer different from the author, edited body. Use the list action Publish selected approved versions. | J29: the new version becomes `published`; the old one becomes `archived`; `GET /lessons/<id>` shows the new text; audit log `content.published`. | K29: 2 | L29: apps.content.tests.AdminPublishingTests.test_lead_publishes_and_it_is_audited apps.catalogue.tests.ContentVersionTests.test_publishing_archives_previous | N29: Not run
A30: TC-ADM-05 | B30: Admin | D30: Publishing a draft is refused | E30: P2 | G30: Local | I30: select a `draft` version and run the publish action. | J30: warning message; nothing changes. | K30: 1 | L30: apps.catalogue.tests.ContentVersionTests.test_only_approved_can_be_published | N30: Not run
A31: TC-ADM-06 | B31: Admin | D31: Publish a question version | E31: P2 | G31: Local | I31: same as TC-ADM-04 under Assessment → Question versions. | J31: new quizzes use the new wording; attempts already started keep the old version. | K31: 1 | L31: apps.content.tests.AdminPublishingTests.test_question_publish_action | N31: Not run
A32: TC-ADM-07 | B32: Admin | D32: Roles | E32: P2 | F32: FR-ACC-9 | G32: Local | I32: as the superuser add a role grant (reviewer, AI Foundations) to a user; add the same active grant again. | J32: first save sets *Granted by* to you and writes audit `role.granted`; second save refused. There is no delete: revoke by setting *Revoked at* (audit `role.revoked`). | K32: 2 | L32: apps.content.tests.RoleAdminTests.test_granting_a_role_is_recorded apps.accounts.tests.RoleTests.test_no_duplicate_active_grant | N32: Not run
A33: TC-ADM-09 | B33: Admin | D33: Curriculum lead publishes only their own subject | E33: P1 | F33: FR-CON-3 | G33: Local | I33: log in to `/admin/` as Lalit (`lalit@test.tutor`). Publish an approved AI Foundations content version. Then, as the superuser, create a Class 8 maths course with a lesson and an approved version; as Lalit try to publish it. | J33: the first publishes (audit `content.published`, actor Lalit); the second is refused with a warning. | K33: 2 | L33: apps.content.tests.PublishPermissionTests.test_lead_for_subject_and_class apps.content.tests.AdminPublishingTests.test_staff_without_role_is_refused | N33: Not run
A34: TC-ADM-10 | B34: Admin | D34: Status can't be set to published by hand | E34: P1 | G34: Local | I34: open an approved content version, change *Status* to `published` and save. Also open a published one and change it to `draft`. | J34: both refused with "Published and archived are set only by the … action". | K34: 2 | L34: apps.content.tests.AdminPublishingTests.test_status_cannot_be_typed_in_as_published apps.content.tests.AdminPublishingTests.test_published_status_cannot_be_changed_back_in_the_form | N34: Not run
A35: TC-ADM-08 | B35: Admin | D35: Mastery and progress are visible | E35: P3 | G35: Local | I35: in `/admin/` open Learning → Mastery states, Mastery events, Lesson progress and Course completions; try to edit a mastery event. | J35: Learning → Mastery states, Mastery events, Lesson progress, Course completions show the smoke-test student's data; mastery events can't be edited. | K35: 0 | N35: Not run
A36: TC-CAT-01 | B36: Catalogue | D36: Facets | E36: P2 | F36: FR-CAT-2 | G36: Local | I36: `GET /catalogue/facets`. | J36: classes 6–12; boards CBSE, ICSE, WBBSE; 5 path stages; disciplines with subjects. | K36: 1 | L36: apps.catalogue.tests.CatalogueApiTests.test_facets | N36: Not run
A37: TC-CAT-02 | B37: Catalogue | D37: Items list shows only published | E37: P1 | F37: FR-CAT-2 | G37: Local | H37: in admin, create a course with status `draft`. | I37: `GET /catalogue/items`. | J37: AI Foundations and "Explore AI (Class 8)" listed; the draft course not listed. | K37: 3 | L37: apps.catalogue.tests.CatalogueApiTests.test_items_lists_published_only smoke:C1 hosted:C1 | N37: Not run
A38: TC-CAT-03 | B38: Catalogue | D38: Filters | E38: P2 | F38: FR-CAT-2 | G38: Local | I38: `?type=course`, `?class_number=8`, `?board=icse`, `?subject=ai-foundations`, `?stage=2`. | J38: board-independent courses (AI Foundations) appear for any class or board; `type=course` excludes programmes. | K38: 2 | L38: apps.catalogue.tests.CatalogueApiTests.test_board_filter_keeps_board_independent_courses apps.catalogue.tests.CatalogueApiTests.test_class_filter | N38: Not run
A39: TC-CAT-04 | B39: Catalogue | D39: Pagination | E39: P3 | G39: Local | I39: `?page_size=1&page=2`. | J39: one result; `page: 2`; `total` equals the unpaginated count. `page_size=500` is capped at 50. | K39: 2 | L39: apps.catalogue.tests.CatalogueApiTests.test_pagination apps.catalogue.test_queries.CatalogueQueryTests.test_items_are_paginated_in_the_database | N39: Not run
A40: TC-CAT-05 | B40: Catalogue | D40: Course page | E40: P1 | G40: Local | I40: `GET /courses/ai-foundations`. | J40: 3 lessons, all `is_free: true` and `has_content: true`; 4 skills; `path_stage_label: "Explore"`; `price_paise: 49900`. | K40: 3 | L40: apps.catalogue.tests.CatalogueApiTests.test_course_detail smoke:C2 hosted:C2 | N40: Not run
...

Sheet Automated tests
A1: Test label | B1: App | C1: Layer | D1: Class | E1: What it proves | F1: Covers manual cases | G1: Run it (from backend/)
A2: apps.accounts.test_api.SignupAndApprovalFlow.test_student_signup_waits_for_parent | B2: accounts | C2: API | D2: SignupAndApprovalFlow | E2: Student signup waits for parent | F2: TC-ACC-01 | G2: python manage.py test apps.accounts.test_api.SignupAndApprovalFlow.test_student_signup_waits_for_parent --settings=config.settings.test
A3: apps.accounts.test_api.SignupAndApprovalFlow.test_full_approval | B3: accounts | C3: API | D3: SignupAndApprovalFlow | E3: Full approval | F3: TC-ACC-02, TC-CON-02 | G3: python manage.py test apps.accounts.test_api.SignupAndApprovalFlow.test_full_approval --settings=config.settings.test
A4: apps.accounts.test_api.SignupAndApprovalFlow.test_parent_must_verify_contact_first | B4: accounts | C4: API | D4: SignupAndApprovalFlow | E4: Parent must verify contact first | F4: TC-CON-03 | G4: python manage.py test apps.accounts.test_api.SignupAndApprovalFlow.test_parent_must_verify_contact_first --settings=config.settings.test
A5: apps.accounts.test_api.SignupAndApprovalFlow.test_not_my_child | B5: accounts | C5: API | D5: SignupAndApprovalFlow | E5: Not my child | F5: TC-CON-06 | G5: python manage.py test apps.accounts.test_api.SignupAndApprovalFlow.test_not_my_child --settings=config.settings.test
A6: apps.accounts.test_api.SignupAndApprovalFlow.test_resend_limit | B6: accounts | C6: API | D6: SignupAndApprovalFlow | E6: Resend limit | F6: TC-CON-07 | G6: python manage.py test apps.accounts.test_api.SignupAndApprovalFlow.test_resend_limit --settings=config.settings.test
A7: apps.accounts.test_api.SignupAndApprovalFlow.test_change_parent_contact | B7: accounts | C7: API | D7: SignupAndApprovalFlow | E7: Change parent contact | F7: TC-CON-08 | G7: python manage.py test apps.accounts.test_api.SignupAndApprovalFlow.test_change_parent_contact --settings=config.settings.test
A8: apps.accounts.test_api.LoginAndErrors.test_login_with_plain_10_digit_mobile | B8: accounts | C8: API | D8: LoginAndErrors | E8: Login with plain 10 digit mobile | F8: TC-ACC-05 | G8: python manage.py test apps.accounts.test_api.LoginAndErrors.test_login_with_plain_10_digit_mobile --settings=config.settings.test
A9: apps.accounts.test_api.LoginAndErrors.test_wrong_password | B9: accounts | C9: API | D9: LoginAndErrors | E9: Wrong password | F9: TC-ACC-06 | G9: python manage.py test apps.accounts.test_api.LoginAndErrors.test_wrong_password --settings=config.settings.test
A10: apps.accounts.test_api.LoginAndErrors.test_duplicate_signup | B10: accounts | C10: API | D10: LoginAndErrors | E10: Duplicate signup | F10: TC-ACC-03 | G10: python manage.py test apps.accounts.test_api.LoginAndErrors.test_duplicate_signup --settings=config.settings.test
A11: apps.accounts.test_api.LoginAndErrors.test_validation_error_format | B11: accounts | C11: API | D11: LoginAndErrors | E11: Validation error format | F11: TC-ACC-04 | G11: python manage.py test apps.accounts.test_api.LoginAndErrors.test_validation_error_format --settings=config.settings.test
A12: apps.accounts.test_api.LoginAndErrors.test_me_requires_login | B12: accounts | C12: API | D12: LoginAndErrors | E12: Me requires login | G12: python manage.py test apps.accounts.test_api.LoginAndErrors.test_me_requires_login --settings=config.settings.test
A13: apps.accounts.test_api.LoginAndErrors.test_otp_not_sent_to_unknown_contact | B13: accounts | C13: API | D13: LoginAndErrors | E13: Otp not sent to unknown contact | F13: TC-ACC-10, TC-SEC-10 | G13: python manage.py test apps.accounts.test_api.LoginAndErrors.test_otp_not_sent_to_unknown_contact --settings=config.settings.test
A14: apps.accounts.test_api.LoginAndErrors.test_password_reset | B14: accounts | C14: API | D14: LoginAndErrors | E14: Password reset | F14: TC-ACC-08 | G14: python manage.py test apps.accounts.test_api.LoginAndErrors.test_password_reset --settings=config.settings.test
A15: apps.accounts.test_api.ParentManagesChildren.test_add_child_withdraw_and_restore | B15: accounts | C15: API | D15: ParentManagesChildren | E15: Add child withdraw and restore | F15: TC-CON-10, TC-CON-11 | G15: python manage.py test apps.accounts.test_api.ParentManagesChildren.test_add_child_withdraw_and_restore --settings=config.settings.test
A16: apps.accounts.test_api.ParentManagesChildren.test_other_parent_cannot_touch_child | B16: accounts | C16: API | D16: ParentManagesChildren | E16: Other parent cannot touch child | F16: TC-SEC-02 | G16: python manage.py test apps.accounts.test_api.ParentManagesChildren.test_other_parent_cannot_touch_child --settings=config.settings.test
A17: apps.accounts.test_api.SecureByDefaultTests.test_docs_page_sends_csrf_token | B17: accounts | C17: API | D17: SecureByDefaultTests | E17: TC-SET-3: the /docs page must send X-CSRFToken so logged-in POSTs work from Swagger. | F17: TC-SET-3 | G17: python manage.py test apps.accounts.test_api.SecureByDefaultTests.test_docs_page_sends_csrf_token --settings=config.settings.test
A18: apps.accounts.test_api.SecureByDefaultTests.test_public_endpoints_stay_public | B18: accounts | C18: API | D18: SecureByDefaultTests | E18: Public endpoints stay public | G18: python manage.py test apps.accounts.test_api.SecureByDefaultTests.test_public_endpoints_stay_public --settings=config.settings.test
A19: apps.accounts.test_api.SecureByDefaultTests.test_protected_endpoints_need_login | B19: accounts | C19: API | D19: SecureByDefaultTests | E19: Protected endpoints need login | F19: TC-SEC-01 | G19: python manage.py test apps.accounts.test_api.SecureByDefaultTests.test_protected_endpoints_need_login --settings=config.settings.test
A20: apps.accounts.test_dev_tools.SeedTestAccountsTests.test_every_account_can_log_in_by_mobile_and_email | B20: accounts | C20: Integration | D20: SeedTestAccountsTests | E20: Every account can log in by mobile and email | G20: python manage.py test apps.accounts.test_dev_tools.SeedTestAccountsTests.test_every_account_can_log_in_by_mobile_and_email --settings=config.settings.test
A21: apps.accounts.test_dev_tools.SeedTestAccountsTests.test_student_states | B21: accounts | C21: Integration | D21: SeedTestAccountsTests | E21: Student states | G21: python manage.py test apps.accounts.test_dev_tools.SeedTestAccountsTests.test_student_states --settings=config.settings.test
A22: apps.accounts.test_dev_tools.SeedTestAccountsTests.test_parent_is_guardian_of_the_active_students_only | B22: accounts | C22: Integration | D22: SeedTestAccountsTests | E22: Parent is guardian of the active students only | G22: python manage.py test apps.accounts.test_dev_tools.SeedTestAccountsTests.test_parent_is_guardian_of_the_active_students_only --settings=config.settings.test
A23: apps.accounts.test_dev_tools.SeedTestAccountsTests.test_asha_has_nothing_and_esha_has_ai_foundations | B23: accounts | C23: Integration | D23: SeedTestAccountsTests | E23: Asha has nothing and esha has ai foundations | G23: python manage.py test apps.accounts.test_dev_tools.SeedTestAccountsTests.test_asha_has_nothing_and_esha_has_ai_foundations --settings=config.settings.test
A24: apps.accounts.test_dev_tools.SeedTestAccountsTests.test_teacher_can_author_and_review_but_not_publish | B24: accounts | C24: Integration | D24: SeedTestAccountsTests | E24: Teacher can author and review but not publish | G24: python manage.py test apps.accounts.test_dev_tools.SeedTestAccountsTests.test_teacher_can_author_and_review_but_not_publish --settings=config.settings.test
A25: apps.accounts.test_dev_tools.SeedTestAccountsTests.test_lead_can_open_admin_and_publish_ai_foundations | B25: accounts | C25: Integration | D25: SeedTestAccountsTests | E25: Lead can open admin and publish ai foundations | G25: python manage.py test apps.accounts.test_dev_tools.SeedTestAccountsTests.test_lead_can_open_admin_and_publish_ai_foundations --settings=config.settings.test
A26: apps.accounts.test_dev_tools.SeedTestAccountsTests.test_running_again_resets_instead_of_duplicating | B26: accounts | C26: Integration | D26: SeedTestAccountsTests | E26: Running again resets instead of duplicating | G26: python manage.py test apps.accounts.test_dev_tools.SeedTestAccountsTests.test_running_again_resets_instead_of_duplicating --settings=config.settings.test
A27: apps.accounts.test_ensure_superuser.EnsureSuperuserTests.test_skips_when_not_configured | B27: accounts | C27: Integration | D27: EnsureSuperuserTests | E27: Skips when not configured | G27: python manage.py test apps.accounts.test_ensure_superuser.EnsureSuperuserTests.test_skips_when_not_configured --settings=config.settings.test
A28: apps.accounts.test_ensure_superuser.EnsureSuperuserTests.test_creates_superuser_once | B28: accounts | C28: Integration | D28: EnsureSuperuserTests | E28: Creates superuser once | G28: python manage.py test apps.accounts.test_ensure_superuser.EnsureSuperuserTests.test_creates_superuser_once --settings=config.settings.test
A29: apps.accounts.test_ensure_superuser.EnsureSuperuserTests.test_never_resets_an_existing_password | B29: accounts | C29: Integration | D29: EnsureSuperuserTests | E29: Never resets an existing password | G29: python manage.py test apps.accounts.test_ensure_superuser.EnsureSuperuserTests.test_never_resets_an_existing_password --settings=config.settings.test
A30: apps.accounts.test_ensure_superuser.EnsureSuperuserTests.test_never_promotes_an_existing_ordinary_account | B30: accounts | C30: Integration | D30: EnsureSuperuserTests | E30: Never promotes an existing ordinary account | G30: python manage.py test apps.accounts.test_ensure_superuser.EnsureSuperuserTests.test_never_promotes_an_existing_ordinary_account --settings=config.settings.test
A31: apps.accounts.test_ensure_superuser.EnsureSuperuserTests.test_weak_password_is_refused | B31: accounts | C31: Integration | D31: EnsureSuperuserTests | E31: Weak password is refused | G31: python manage.py test apps.accounts.test_ensure_superuser.EnsureSuperuserTests.test_weak_password_is_refused --settings=config.settings.test
... A34: apps.accounts.test_security.ClientIpTests.test_header_ignored_without_trusted_proxies | B34: accounts | C34: Unit | D34: ClientIpTests | E34: Header ignored without trusted proxies | G34: python manage.py test apps.accounts.test_security.ClientIpTests.test_header_ignored_without_trusted_proxies --settings=config.settings.test
A35: apps.accounts.test_security.ClientIpTests.test_forged_left_entries_are_ignored | B35: accounts | C35: Unit | D35: ClientIpTests | E35: Forged left entries are ignored | F35: TC-SEC-16 | G35: python manage.py test apps.accounts.test_security.ClientIpTests.test_forged_left_entries_are_ignored --settings=config.settings.test
A36: apps.accounts.test_security.ClientIpTests.test_two_proxies | B36: accounts | C36: Unit | D36: ClientIpTests | E36: Two proxies | G36: python manage.py test apps.accounts.test_security.ClientIpTests.test_two_proxies --settings=config.settings.test
A37: apps.accounts.test_security.ClientIpTests.test_no_header_falls_back_to_remote_addr | B37: accounts | C37: Unit | D37: ClientIpTests | E37: No header falls back to remote addr | G37: python manage.py test apps.accounts.test_security.ClientIpTests.test_no_header_falls_back_to_remote_addr --settings=config.settings.test
A38: apps.accounts.test_security.RateLimitTests.test_login_is_rate_limited_per_ip | B38: accounts | C38: API | D38: RateLimitTests | E38: Login is rate limited per ip | F38: TC-SEC-15 | G38: python manage.py test apps.accounts.test_security.RateLimitTests.test_login_is_rate_limited_per_ip --settings=config.settings.test
A39: apps.accounts.test_security.RateLimitTests.test_limit_is_per_client_ip | B39: accounts | C39: API | D39: RateLimitTests | E39: Limit is per client ip | G39: python manage.py test apps.accounts.test_security.RateLimitTests.test_limit_is_per_client_ip --settings=config.settings.test
A40: apps.accounts.test_security.RateLimitTests.test_forging_x_forwarded_for_does_not_escape_the_limit | B40: accounts | C40: API | D40: RateLimitTests | E40: Forging x forwarded for does not escape the limit | F40: TC-SEC-16 | G40: python manage.py test apps.accounts.test_security.RateLimitTests.test_forging_x_forwarded_for_does_not_escape_the_limit --settings=config.settings.test
A41: apps.accounts.test_security.RateLimitTests.test_signup_is_rate_limited | B41: accounts | C41: API | D41: RateLimitTests | E41: Signup is rate limited | G41: python manage.py test apps.accounts.test_security.RateLimitTests.test_signup_is_rate_limited --settings=config.settings.test
A42: apps.accounts.test_security.RateLimitTests.test_one_time_code_endpoints_are_rate_limited | B42: accounts | C42: API | D42: RateLimitTests | E42: One time code endpoints are rate limited | F42: TC-ACC-09 | G42: python manage.py test apps.accounts.test_security.RateLimitTests.test_one_time_code_endpoints_are_rate_limited --settings=config.settings.test
...

Sheet Smoke checks
A1: Mode | B1: Check | C1: What it checks | D1: Command (from backend/)
A2: Hosted (read-only) | B2: hosted:H0 | C2: site reachable | D2: python qa/smoke_test.py --hosted --base <site URL>
A3: Hosted (read-only) | B3: hosted:H1 | C3: healthy and database reachable | D3: python qa/smoke_test.py --hosted --base <site URL>
A4: Hosted (read-only) | B4: hosted:H2 | C4: HSTS header present | D4: python qa/smoke_test.py --hosted --base <site URL>
A5: Hosted (read-only) | B5: hosted:H3 | C5: nosniff header present | D5: python qa/smoke_test.py --hosted --base <site URL>
A6: Hosted (read-only) | B6: hosted:H4 | C6: plain HTTP redirects to HTTPS | D6: python qa/smoke_test.py --hosted --base <site URL>
A7: Hosted (read-only) | B7: hosted:H5 | C7: root page points to the API docs | D7: python qa/smoke_test.py --hosted --base <site URL>
A8: Hosted (read-only) | B8: hosted:H6 | C8: CSRF cookie is Secure | D8: python qa/smoke_test.py --hosted --base <site URL>
A9: Hosted (read-only) | B9: hosted:C1 | C9: catalogue lists AI Foundations | D9: python qa/smoke_test.py --hosted --base <site URL>
A10: Hosted (read-only) | B10: hosted:C2 | C10: course has lessons and skills | D10: python qa/smoke_test.py --hosted --base <site URL>
A11: Hosted (read-only) | B11: hosted:C3 | C11: course has a free lesson | D11: python qa/smoke_test.py --hosted --base <site URL>
A12: Hosted (read-only) | B12: hosted:C4 | C12: free lesson preview readable without login | D12: python qa/smoke_test.py --hosted --base <site URL>
... A43: Local journey | B43: smoke:X2 | C43: unknown course is 404 | D43: python qa/smoke_test.py

Sheet Traceability
A1: Requirement | B1: Area | C1: Requirement text | D1: Build status | E1: Manual cases | F1: # manual | G1: # automated | H1: Coverage
A2: FR-ACC-1 | B2: ACC | C2: Sign-up and login with email or mobile (10-digit Indian numbers accepted and stored as +91…) | D2: Implemented | E2: TC-ACC-01, TC-ACC-03, TC-ACC-04, TC-ACC-05, TC-DEMO-01 | F2: 5 | G2: 8 | H2: =IF(F2=0,"No manual case",IF(G2=0,"Manual only","Manual + automated")) -> Manual + automated
A3: FR-ACC-2 | B3: ACC | C3: Contact verification and password reset by 6-digit one-time code (10-minute expiry, 5 attempts, 5 codes / 10 min) | D3: Implemented | E3: TC-ACC-02, TC-ACC-08, TC-ACC-09 | F3: 3 | G3: 4 | H3: =IF(F3=0,"No manual case",IF(G3=0,"Manual only","Manual + automated")) -> Manual + automated
A4: FR-ACC-3 | B4: ACC | C4: Codes are never sent to unregistered contacts, so the API doesn't reveal who is registered | D4: Implemented | E4: TC-ACC-10, TC-SEC-10, TC-SEC-14 | F4: 3 | G4: 3 | H4: =IF(F4=0,"No manual case",IF(G4=0,"Manual only","Manual + automated")) -> Manual + automated
A5: FR-ACC-4 | B5: ACC | C5: Student accounts start `awaiting_consent`; parent approves via a hashed, 7-day link | D5: Implemented | E5: TC-ACC-01, TC-CON-01, TC-CON-02 | F5: 3 | G5: 6 | H5: =IF(F5=0,"No manual case",IF(G5=0,"Manual only","Manual + automated")) -> Manual + automated
A6: FR-ACC-5 | B6: ACC | C6: Consent records store the exact consent-text version, time and IP | D6: Implemented | E6: TC-CON-02, TC-SEC-06 | F6: 2 | G6: 4 | H6: =IF(F6=0,"No manual case",IF(G6=0,"Manual only","Manual + automated")) -> Manual + automated
A7: FR-ACC-6 | B7: ACC | C7: One active primary guardian per student (v1) | D7: Implemented | E7: TC-CON-09 | F7: 1 | G7: 1 | H7: =IF(F7=0,"No manual case",IF(G7=0,"Manual only","Manual + automated")) -> Manual + automated
A8: FR-ACC-7 | B8: ACC | C8: Withdrawal pauses the student immediately; restore reactivates | D8: Implemented | E8: TC-CON-11 | F8: 1 | G8: 5 | H8: =IF(F8=0,"No manual case",IF(G8=0,"Manual only","Manual + automated")) -> Manual + automated
A9: FR-ACC-8 | B9: ACC | C9: Unapproved student accounts deleted after 30 days; data deleted 30 days after withdrawal | D9: Planned (scheduled job) | F9: 0 | G9: 0 | H9: =IF(F9=0,"No manual case",IF(G9=0,"Manual only","Manual + automated")) -> No manual case
A10: FR-ACC-9 | B10: ACC | C10: Roles (author, reviewer, batch teacher, curriculum lead, operations, super admin) scoped by subject and class | D10: Implemented (model; publishing and role management enforced) | E10: TC-ADM-07 | F10: 1 | G10: 2 | H10: =IF(F10=0,"No manual case",IF(G10=0,"Manual only","Manual + automated")) -> Manual + automated
A11: FR-CAT-1 | B11: CAT | C11: Discipline → Subject → Course → Module → Lesson; skills with prerequisites; board chapter mappings | D11: Implemented | F11: 0 | G11: 0 | H11: =IF(F11=0,"No manual case",IF(G11=0,"Manual only","Manual + automated")) -> No manual case
A12: FR-CAT-2 | B12: CAT | C12: Public list filtered by class, board, subject and stage; board-independent courses always match | D12: Implemented | E12: TC-CAT-01, TC-CAT-02, TC-CAT-03, TC-DEMO-06 | F12: 4 | G12: 7 | H12: =IF(F12=0,"No manual case",IF(G12=0,"Manual only","Manual + automated")) -> Manual + automated
A13: FR-CAT-3 | B13: CAT | C13: First module of a course readable free (without AI tutor) | D13: Implemented | E13: TC-CAT-08, TC-CAT-09 | F13: 2 | G13: 3 | H13: =IF(F13=0,"No manual case",IF(G13=0,"Manual only","Manual + automated")) -> Manual + automated
A14: FR-CON-1 | B14: CON | C14: Every lesson and question edit is a new version; published versions are immutable | D14: Implemented | E14: TC-SEC-08 | F14: 1 | G14: 2 | H14: =IF(F14=0,"No manual case",IF(G14=0,"Manual only","Manual + automated")) -> Manual + automated
A15: FR-CON-2 | B15: CON | C15: One published version per lesson/question; reviewer ≠ author (database-enforced) | D15: Implemented | E15: TC-DEMO-11, TC-SEC-09 | F15: 2 | G15: 2 | H15: =IF(F15=0,"No manual case",IF(G15=0,"Manual only","Manual + automated")) -> Manual + automated
A16: FR-CON-3 | B16: CON | C16: Publishing archives the previous version and re-indexes the lesson for the tutor | D16: Archive implemented; re-index planned | E16: TC-ADM-04, TC-ADM-09, TC-DEMO-07, TC-SEC-17 | F16: 4 | G16: 7 | H16: =IF(F16=0,"No manual case",IF(G16=0,"Manual only","Manual + automated")) -> Manual + automated
A17: FR-LRN-1 | B17: LRN | C17: Lessons, quizzes and the tutor require an active (consented) student account | D17: Implemented | E17: TC-DEMO-02, TC-LRN-01, TC-LRN-02 | F17: 3 | G17: 6 | H17: =IF(F17=0,"No manual case",IF(G17=0,"Manual only","Manual + automated")) -> Manual + automated
A18: FR-LRN-2 | B18: LRN | C18: Paid lessons require an active entitlement to the course or a programme containing it | D18: Implemented | E18: TC-DEMO-03, TC-LRN-03, TC-LRN-04 | F18: 3 | G18: 3 | H18: =IF(F18=0,"No manual case",IF(G18=0,"Manual only","Manual + automated")) -> Manual + automated
A19: FR-LRN-3 | B19: LRN | C19: Quiz answers are never sent to the client before answering; each answer references the exact question version shown | D19: Implemented | E19: TC-QZ-01 | F19: 1 | G19: 2 | H19: =IF(F19=0,"No manual case",IF(G19=0,"Manual only","Manual + automated")) -> Manual + automated
A20: FR-LRN-4 | B20: LRN | C20: Mastery per skill: `score ← score + 0.35 × (credit − score)`; each hint removes 25% of credit; *mastered* needs score ≥ 0.75 and ≥ 3 answers | D20: Implemented | E20: TC-QZ-03, TC-MAS-01, TC-MAS-02 | F20: 3 | G20: 4 | H20: =IF(F20=0,"No manual case",IF(G20=0,"Manual only","Manual + automated")) -> Manual + automated
A21: FR-LRN-5 | B21: LRN | C21: Every mastery change is logged with the answer that caused it | D21: Implemented | E21: TC-DEMO-04, TC-MAS-01 | F21: 2 | G21: 3 | H21: =IF(F21=0,"No manual case",IF(G21=0,"Manual only","Manual + automated")) -> Manual + automated
A22: FR-LRN-6 | B22: LRN | C22: Course complete = all lessons finished and every taught skill at least *developing* | D22: Implemented | E22: TC-DEMO-04, TC-MAS-03 | F22: 2 | G22: 3 | H22: =IF(F22=0,"No manual case",IF(G22=0,"Manual only","Manual + automated")) -> Manual + automated
A23: FR-LRN-7 | B23: LRN | C23: Today: next unfinished lesson, weakest-skill review, streak counted in IST | D23: Implemented | E23: TC-TDY-01 | F23: 1 | G23: 2 | H23: =IF(F23=0,"No manual case",IF(G23=0,"Manual only","Manual + automated")) -> Manual + automated
A24: FR-LRN-8 | B24: LRN | C24: Adaptive warm-up check using skill prerequisites | D24: Planned | F24: 0 | G24: 0 | H24: =IF(F24=0,"No manual case",IF(G24=0,"Manual only","Manual + automated")) -> No manual case
A25: FR-AI-1 | B25: AI | C25: Tutor modes Explain / Socratic / Hint, grounded in published lesson content with cited sections | D25: Planned | F25: 0 | G25: 0 | H25: =IF(F25=0,"No manual case",IF(G25=0,"Manual only","Manual + automated")) -> No manual case
A26: FR-AI-2 | B26: AI | C26: Daily message limit per student (default 50, admin-adjustable) | D26: Planned | F26: 0 | G26: 0 | H26: =IF(F26=0,"No manual case",IF(G26=0,"Manual only","Manual + automated")) -> No manual case
A27: FR-AI-3 | B27: AI | C27: Safety check on every message; flags routed to operations | D27: Planned | F27: 0 | G27: 0 | H27: =IF(F27=0,"No manual case",IF(G27=0,"Manual only","Manual + automated")) -> No manual case
A28: FR-COM-1 | B28: COM | C28: Razorpay checkout; entitlement created only from a signature-verified webhook | D28: Planned | F28: 0 | G28: 0 | H28: =IF(F28=0,"No manual case",IF(G28=0,"Manual only","Manual + automated")) -> No manual case
A29: FR-COM-2 | B29: COM | C29: Idempotency keys on order creation | D29: Planned | F29: 0 | G29: 0 | H29: =IF(F29=0,"No manual case",IF(G29=0,"Manual only","Manual + automated")) -> No manual case
A30: FR-BAT-1 | B30: BAT | C30: Batches with class, board, mode, city, centre, teacher, seats, price; sessions with meeting links; attendance | D30: Planned | F30: 0 | G30: 0 | H30: =IF(F30=0,"No manual case",IF(G30=0,"Manual only","Manual + automated")) -> No manual case
A31: FR-OPS-1 | B31: OPS | C31: Append-only audit log of consent, role, publishing, refund and suspension changes | D31: Implemented (consent, publishing, roles) | E31: TC-SEC-07 | F31: 1 | G31: 1 | H31: =IF(F31=0,"No manual case",IF(G31=0,"Manual only","Manual + automated")) -> Manual + automated
A32: NFR-SEC-1 | B32: Security | C32: Server-side authorization on every endpoint; the browser talks only to Django | D32: — | E32: TC-HOST-03, TC-SEC-01 | F32: 2 | G32: 4 | H32: =IF(F32=0,"No manual case",IF(G32=0,"Manual only","Manual + automated")) -> Manual + automated
A33: NFR-SEC-2 | B33: Security | C33: Session cookies HttpOnly, Secure (prod), SameSite=Lax; CSRF on state-changing requests | D33: — | E33: TC-SET-3, TC-HOST-04 | F33: 2 | G33: 3 | H33: =IF(F33=0,"No manual case",IF(G33=0,"Manual only","Manual + automated")) -> Manual + automated
A34: NFR-SEC-3 | B34: Security | C34: Secrets only in environment variables; link tokens and one-time codes stored as SHA-256 hashes | D34: — | E34: TC-SEC-05 | F34: 1 | G34: 1 | H34: =IF(F34=0,"No manual case",IF(G34=0,"Manual only","Manual + automated")) -> Manual + automated
A35: NFR-SEC-4 | B35: Security | C35: Brute-force protection: rate limits on login, sign-up, one-time codes and consent links; per-account login lockout | D35: — | E35: TC-SEC-13, TC-SEC-15, TC-SEC-16 | F35: 3 | G35: 5 | H35: =IF(F35=0,"No manual case",IF(G35=0,"Manual only","Manual + automated")) -> Manual + automated
A36: NFR-SEC-5 | B36: Security | C36: Least privilege in the back office: publishing, role grants and admin access decided by role grants, not staff status | D36: — | E36: TC-DEMO-08, TC-DEMO-09, TC-DEMO-10, TC-SEC-18 | F36: 4 | G36: 6 | H36: =IF(F36=0,"No manual case",IF(G36=0,"Manual only","Manual + automated")) -> Manual + automated
A37: NFR-PRIV-1 | B37: Privacy | C37: Data minimisation (class, not date of birth); AI service receives a pseudonymous learner reference only | D37: — | E37: TC-SEC-12 | F37: 1 | G37: 0 | H37: =IF(F37=0,"No manual case",IF(G37=0,"Manual only","Manual + automated")) -> Manual only
A38: NFR-PRIV-2 | B38: Privacy | C38: Parent can withdraw consent, export and delete the child's data | D38: — | F38: 0 | G38: 0 | H38: =IF(F38=0,"No manual case",IF(G38=0,"Manual only","Manual + automated")) -> No manual case
A39: NFR-PERF-1 | B39: Performance | C39: API p95 < 300 ms for non-AI endpoints at launch load; tutor first token < 3 s | D39: — | F39: 0 | G39: 0 | H39: =IF(F39=0,"No manual case",IF(G39=0,"Manual only","Manual + automated")) -> No manual case
A40: NFR-AVAIL-1 | B40: Availability | C40: Health endpoint for platform checks; database backups with a tested restore before launch | D40: — | E40: TC-SET-1, TC-HOST-01 | F40: 2 | G40: 6 | H40: =IF(F40=0,"No manual case",IF(G40=0,"Manual only","Manual + automated")) -> Manual + automated
...

Sheet Demo accounts
A1: Key | B1: Name | C1: Mobile | D1: Email | E1: Role / state | F1: Use it to test
A2: parent | B2: Test Parent | C2: 9000000001 | D2: parent@test.tutor | E2: Parent of Asha, Esha, Kabir | F2: Parent views, withdraw/restore consent, add a child
A3: priya | B3: Priya Nair | C3: 9000000011 | D3: priya@test.tutor | E3: Parent of Meera, Zoya, Ishaan | F3: Several children, different classes
A4: rahul | B4: Rahul Das | C4: 9000000012 | D4: rahul@test.tutor | E4: Wasim's parent; approval pending | F4: Approval flow (local: link in the dev outbox)
A5: farhan | B5: Farhan Ali | C5: 9000000013 | D5: farhan@test.tutor | E5: Withdrew consent for Rohan | F5: Restoring consent
A6: student_active | B6: Asha Active | C6: 9000000002 | D6: asha@test.tutor | E6: Class 8 CBSE, active, nothing bought | F6: Free lessons only; paid lessons refused
A7: student_enrolled | B7: Esha Enrolled | C7: 9000000003 | D7: esha@test.tutor | E7: Class 8 CBSE, AI Foundations | F7: One quiz taken; continue the course
A8: student_waiting | B8: Wasim Waiting | C8: 9000000004 | D8: wasim@test.tutor | E8: Class 8, awaiting consent | F8: Everything except browsing is blocked
A9: kabir | B9: Kabir Sen | C9: 9000000021 | D9: kabir@test.tutor | E9: Class 8 CBSE, Class 8 Foundation programme | F9: Rich record: AI Foundations completed, 7 quizzes, weak on inverses (review item)
A10: meera | B10: Meera Nair | C10: 9000000022 | D10: meera@test.tutor | E10: Class 11 ICSE, Physics 11 | F10: Mid-course, 3-day streak
A11: zoya | B11: Zoya Nair | C11: 9000000023 | D11: zoya@test.tutor | E11: Class 6 CBSE, Class 6 Maths Start | F11: 5-day streak, a quiz retake
A12: rohan | B12: Rohan Ali | C12: 9000000024 | D12: rohan@test.tutor | E12: Class 8 ICSE, paused (consent withdrawn) | F12: Blocked with `consent_required`; history kept
... A20: omar | B20: Omar Sheikh | C20: 9000000043 | D20: omar@test.tutor | E20: Operations | F20: Can: Look up users, grant enrolments (entitlements). Cannot: Publish anything, grant roles

Sheet Bug log
A1: Bug ID | B1: TC ID | C1: Title | D1: Severity | E1: Environment | F1: Steps to reproduce | G1: Expected | H1: Actual | I1: Reported by | J1: Reported on | K1: Status | L1: Notes
A2: BUG-001 | B2: TC-QZ-06 | C2: Answering twice returns 500 instead of 409 | D2: High | E2: Local | F2: Start quiz; answer position 1; answer position 1 again | G2: 409 conflict | H2: 500 server error | I2: Tester name | J2: 46296 | K2: Open | L2: Example row: replace or delete
